<?xml version="1.0"?>
<robot name="sam_bot" xmlns:xacro="http://ros.org/wiki/xacro">
  <!-- Define robot constants -->
  <xacro:property name="base_width" value="0.15"/>
  <xacro:property name="base_length" value="0.20"/>
  <xacro:property name="base_height" value="0.18"/>
  <xacro:property name="base_mass" value="1.0"/>

  <xacro:property name="wheel_radius" value="0.10"/>
  <xacro:property name="wheel_width" value="0.04"/>
  <xacro:property name="wheel_ygap" value="0.025"/>
  <xacro:property name="wheel_zoff" value="0.05"/>
  <xacro:property name="wheel_xoff" value="0.12"/>
  <xacro:property name="wheel_mass" value="1.0"/>

  <xacro:property name="ixx_box" value="${(1/12.0) * base_mass * (base_height**2 + base_length**2)}"/>
  <xacro:property name="iyy_box" value="${(1/12.0) * base_mass * (base_width**2 + base_length**2)}"/>
  <xacro:property name="izz_box" value="${(1/12.0) * base_mass * (base_width**2 + base_height**2)}"/>
  
  <xacro:property name="ixxyy_wheel" value="${(1/12.0) * wheel_mass * (3 * wheel_radius**2 + wheel_width**2)}"/>
  <xacro:property name="izz_wheel" value="${(0.5) * wheel_mass * wheel_radius**2}"/>

  <xacro:property name="caster_xoff" value="0.14"/>

  <!-- Robot Base -->
  <link name="base_link">
    <visual>
      <geometry>
        <box size="${base_length} ${base_width} ${base_height}"/>
      </geometry>
      <material name="Cyan">
        <color rgba="0 1.0 1.0 1.0"/>
      </material>
    </visual>
    <collision>
        <geometry>
            <box size="${base_length} ${base_width} ${base_height}"/> 
        </geometry>
    </collision>
    <inertial>
        <mass value="1.0"/>
        <origin xyz="0 0 0"/>
        <inertia ixx="${ixx_box}" ixy="0.0" ixz="0.0" iyy="${iyy_box}" iyz="0.0" izz="${izz_box}"/>
    </inertial>
  </link>

  <!-- Robot Footprint -->
  <link name="base_footprint"/>

  <joint name="base_joint" type="fixed">
    <parent link="base_link"/>
    <child link="base_footprint"/>
    <origin xyz="0.0 0.0 ${-(wheel_radius+wheel_zoff)}" rpy="0 0 0"/>
  </joint>

  <!-- Wheels -->
  <xacro:macro name="wheel" params="prefix x_reflect y_reflect">
    <link name="${prefix}_link">
      <visual>
        <origin xyz="0 0 0" rpy="${pi/2} 0 0"/>
        <geometry>
            <cylinder radius="${wheel_radius}" length="${wheel_width}"/>
        </geometry>
        <material name="Gray">
          <color rgba="0.5 0.5 0.5 1.0"/>
        </material>
      </visual>
        <collision>
            <geometry>
                <cylinder radius="${wheel_radius}" length="${wheel_width}"/>
            </geometry>
        </collision>
        <inertial>
            <mass value="1.0"/>
            <origin xyz="0 0 0"/>
            <inertia ixx="${ixxyy_wheel}" ixy="0.0" ixz="0.0" iyy="${ixxyy_wheel}" iyz="0.0" izz="${izz_wheel}"/>
        </inertial>
    </link>

    <joint name="${prefix}_joint" type="continuous">
      <parent link="base_link"/>
      <child link="${prefix}_link"/>
      <origin xyz="${x_reflect*wheel_xoff} ${y_reflect*(base_width/2+wheel_ygap)} ${-wheel_zoff}" rpy="0 0 0"/>
      <axis xyz="0 1 0"/>
    </joint>
  </xacro:macro>

  <xacro:wheel prefix="drivewhl_l" x_reflect="-1" y_reflect="1" />
  <xacro:wheel prefix="drivewhl_r" x_reflect="-1" y_reflect="-1" />

  <!-- Caster Wheel -->
  <link name="front_caster">
    <visual>
      <geometry>
        <sphere radius="${(wheel_radius+wheel_zoff-(base_height/2))}"/>
      </geometry>
      <material name="Cyan">
        <color rgba="0 1.0 1.0 1.0"/>
      </material>
    </visual>
  </link>

  <joint name="caster_joint" type="fixed">
    <parent link="base_link"/>
    <child link="front_caster"/>
    <origin xyz="${caster_xoff} 0.0 ${-(base_height/2)}" rpy="0 0 0"/>
  </joint>

</robot>